{"context": "python(CPython)\u3067\u4f8b\u5916\u3092\u6295\u3052\u308b\u3068\u3001\u4f8b\u5916\u3092\u6295\u3052\u305f\u30d5\u30ec\u30fc\u30e0\u304c\u4f8b\u5916\u3092\u30ad\u30e3\u30c3\u30c1\u3057\u305f\u30d5\u30ec\u30fc\u30e0\u306b\u8ffd\u52a0\u3055\u308c\u308b\u3002\n\u3053\u306e\u305f\u3081\u3001\u30ea\u30d5\u30a1\u30ec\u30f3\u30b9\u30ab\u30a6\u30f3\u30c8\u306e\u52d5\u4f5c\u304c\u975e\u81ea\u660e\u306b\u306a\u308a\u3001\u30aa\u30d6\u30b8\u30a7\u30af\u30c8\u306e\u5bff\u547d\u304c\u610f\u56f3\u305b\u305a\u5ef6\u9577\u3055\u308c\u308b\u3002\nclass Foo(Exception):\n    def __init__(self):\n        print 'construt'\n\n    def __del__(self):\n        print 'destruct'\n\n    def raiseError(self):\n        raise Exception()\n\ndef main ():\n    print 'enter main'\n    foo = Foo()\n    try:\n        foo.raiseError()\n    except:\n        print 'catch exception'\n    foo = None\n    print 'exit main'\n\ntry:\n    main()\nfinally:\n    print 'finish'\n\n\u4ee5\u4e0a\u306e\u30b3\u30fc\u30c9\u306e\u51fa\u529b\u306f\u4ee5\u4e0b\u306e\u3088\u3046\u306b\u306a\u308b\u3002\nenter main\nconstrut\ncatch exception\nexit main\ndestruct\nfinish\n\n\u4ee5\u4e0a\u306e\u3088\u3046\u306b\u3001main\u5185\u306efoo\u30aa\u30d6\u30b8\u30a7\u30af\u30c8\u3092'exit main'\u306e\u524d\u306b\u89e3\u653e\u3059\u308b\u4e8b\u3092\u610f\u56f3\u3057\u305f\u3068\u3057\u3066\u3082main\u306e\u30d5\u30ec\u30fc\u30e0\u304c\u89e3\u653e\u3055\u308c\u308b\u307e\u3067foo\u306e\u5bff\u547d\u304c\u5ef6\u9577\u3055\u308c\u308b\u3002\n\u3053\u308c\u306f\u3001\u4f8b\u5916\u3092\u6295\u3052\u305fraiseError\u5185\u306e\u30d5\u30ec\u30fc\u30e0\u304c\u3001main\u5185\u306e\u30d5\u30ec\u30fc\u30e0\u306b\u4fdd\u6301\u3055\u308c\u3001raiseError\u5185\u306e\u30d5\u30ec\u30fc\u30e0\u306fself = foo\u3092\u4fdd\u6301\u3057\u3066\u3044\u308b\u305f\u3081\u3060\u3002\n\u4f8b\u5916\u30d5\u30ec\u30fc\u30e0\u306e\u89e3\u653e\u306fsys.exc_clear()\u3067\u884c\u3046\u3002\n\u4f3c\u305f\u3088\u3046\u306e\u4e8b\u4f8b\u3068\u3057\u3066\u306f\u3001\u30eb\u30fc\u30d7\u5185\u3067try-catch\u3057\u3066\u3044\u308b\u6642\u306b\u3001\u30eb\u30fc\u30d7\u5185\u3067\u78ba\u4fdd\u3057\u305f\u30aa\u30d6\u30b8\u30a7\u30af\u30c8\u306e\u89e3\u653e\u306e\u30bf\u30a4\u30df\u30f3\u30b0\u304c1\u30eb\u30fc\u30d7\u5206\u305a\u308c\u308b\u7b49\u304c\u3042\u308a\u5f97\u308b\u3002\n\u3053\u308c\u306f\u4f8b\u5916\u30d5\u30ec\u30fc\u30e0\u304c\u6b21\u306e\u30eb\u30fc\u30d7\u3067\u306e\u4f8b\u5916\u30b9\u30ed\u30fc\u306b\u3088\u3063\u3066\u89e3\u653e\u3055\u308c\u308b\u304b\u3089\u3060\u3002\nhttp://stackoverflow.com/questions/8822418/object-not-freed-after-an-exception-raise-in-python-2-7\npython(CPython)\u3067\u4f8b\u5916\u3092\u6295\u3052\u308b\u3068\u3001\u4f8b\u5916\u3092\u6295\u3052\u305f\u30d5\u30ec\u30fc\u30e0\u304c\u4f8b\u5916\u3092\u30ad\u30e3\u30c3\u30c1\u3057\u305f\u30d5\u30ec\u30fc\u30e0\u306b\u8ffd\u52a0\u3055\u308c\u308b\u3002\n\u3053\u306e\u305f\u3081\u3001\u30ea\u30d5\u30a1\u30ec\u30f3\u30b9\u30ab\u30a6\u30f3\u30c8\u306e\u52d5\u4f5c\u304c\u975e\u81ea\u660e\u306b\u306a\u308a\u3001\u30aa\u30d6\u30b8\u30a7\u30af\u30c8\u306e\u5bff\u547d\u304c\u610f\u56f3\u305b\u305a\u5ef6\u9577\u3055\u308c\u308b\u3002\n\n```py \nclass Foo(Exception):\n    def __init__(self):\n        print 'construt'\n    \n    def __del__(self):\n        print 'destruct'\n    \n    def raiseError(self):\n        raise Exception()\n\ndef main ():\n    print 'enter main'\n    foo = Foo()\n    try:\n        foo.raiseError()\n    except:\n        print 'catch exception'\n    foo = None\n    print 'exit main'\n\ntry:\n    main()\nfinally:\n    print 'finish'\n```\n\n\u4ee5\u4e0a\u306e\u30b3\u30fc\u30c9\u306e\u51fa\u529b\u306f\u4ee5\u4e0b\u306e\u3088\u3046\u306b\u306a\u308b\u3002\n\n```text\nenter main\nconstrut\ncatch exception\nexit main\ndestruct\nfinish\n```\n\n\u4ee5\u4e0a\u306e\u3088\u3046\u306b\u3001`main`\u5185\u306e`foo`\u30aa\u30d6\u30b8\u30a7\u30af\u30c8\u3092'exit main'\u306e\u524d\u306b\u89e3\u653e\u3059\u308b\u4e8b\u3092\u610f\u56f3\u3057\u305f\u3068\u3057\u3066\u3082`main`\u306e\u30d5\u30ec\u30fc\u30e0\u304c\u89e3\u653e\u3055\u308c\u308b\u307e\u3067`foo`\u306e\u5bff\u547d\u304c\u5ef6\u9577\u3055\u308c\u308b\u3002\n\u3053\u308c\u306f\u3001\u4f8b\u5916\u3092\u6295\u3052\u305f`raiseError`\u5185\u306e\u30d5\u30ec\u30fc\u30e0\u304c\u3001`main`\u5185\u306e\u30d5\u30ec\u30fc\u30e0\u306b\u4fdd\u6301\u3055\u308c\u3001`raiseError`\u5185\u306e\u30d5\u30ec\u30fc\u30e0\u306f`self = foo`\u3092\u4fdd\u6301\u3057\u3066\u3044\u308b\u305f\u3081\u3060\u3002\n\n\u4f8b\u5916\u30d5\u30ec\u30fc\u30e0\u306e\u89e3\u653e\u306f`sys.exc_clear()`\u3067\u884c\u3046\u3002\n\n\u4f3c\u305f\u3088\u3046\u306e\u4e8b\u4f8b\u3068\u3057\u3066\u306f\u3001\u30eb\u30fc\u30d7\u5185\u3067try-catch\u3057\u3066\u3044\u308b\u6642\u306b\u3001\u30eb\u30fc\u30d7\u5185\u3067\u78ba\u4fdd\u3057\u305f\u30aa\u30d6\u30b8\u30a7\u30af\u30c8\u306e\u89e3\u653e\u306e\u30bf\u30a4\u30df\u30f3\u30b0\u304c1\u30eb\u30fc\u30d7\u5206\u305a\u308c\u308b\u7b49\u304c\u3042\u308a\u5f97\u308b\u3002\n\u3053\u308c\u306f\u4f8b\u5916\u30d5\u30ec\u30fc\u30e0\u304c\u6b21\u306e\u30eb\u30fc\u30d7\u3067\u306e\u4f8b\u5916\u30b9\u30ed\u30fc\u306b\u3088\u3063\u3066\u89e3\u653e\u3055\u308c\u308b\u304b\u3089\u3060\u3002\n\nhttp://stackoverflow.com/questions/8822418/object-not-freed-after-an-exception-raise-in-python-2-7\n", "tags": ["Python", "\u4f8b\u5916"]}