{"context": "\u3061\u3087\u3063\u3068\u77e5\u3063\u305fMkDocs\u3067\u3001\u904b\u7528\u624b\u9806\u66f8\u306a\u3093\u304b\u3092\u7ba1\u7406\u3067\u304d\u305f\u3089\u826f\u3044\u306a\u3001\u3068\u601d\u3044\u3001\u7c21\u5358\u306b\u74b0\u5883\u69cb\u7bc9\u3057\u3088\u3046\u3068\u3057\u305f\u306e\u304c\u59cb\u307e\u308a\u3002\n\u6ce8\u610f\uff01\uff01\n\u3053\u306e\u8a18\u4e8b\u306f\u7d50\u679c\u7684\u306b\u5931\u6557\u3057\u305f\u306e\u3067\u3001\u5b8c\u6210\u306f\u3053\u3061\u3089\u306e\u8a18\u4e8b\u53c2\u7167\u3057\u3066\u3044\u305f\u3060\u304d\u3001\u4ee5\u4e0b\u306e\u5931\u6557\u8ac7\u306f\u304b\u3063\u3068\u3070\u3057\u3066\u304f\u3060\u3055\u3044\u3002\u3002\u3002\n\uff08\u3053\u308c\u306f\u81ea\u5206\u306e\u5099\u5fd8\u9332\u7684\u306a\u3082\u306e\u3067\u3059\uff09\n\n\u524d\u63d0\n\nAWS\u306bAmazonLinux\u306eEC2\u3092\u6e96\u5099\u3057\u3066\u304a\u304f\n\nyum update\u3092\u884c\u3044\u3001\u6700\u65b0\u72b6\u614b\u306b\u3057\u3066\u304a\u304f\n\u5b9f\u884c\u30e6\u30fc\u30b6\u306f\u30c7\u30d5\u30a9\u30eb\u30c8\u306eec2-user\u3068\u3059\u308b\nPython\u74b0\u5883\u306fAmazon Linux\u306e\u30c7\u30d5\u30a9\u30eb\u30c8\uff08Python 2.7.10\uff09\u3092\u7528\u3044\u308b\u3000\u203b2016/4/6\u6642\u70b9\n\n\n\u74b0\u5883\u6e96\u5099\nMkDocs\u3092\u4f7f\u3063\u3066\u30c9\u30ad\u30e5\u30e1\u30f3\u30c8\u306e\u30b5\u30a4\u30c8\u306e\u81ea\u52d5\u3067\u3053\u3057\u3089\u3048\u308b\u3092\u53c2\u8003\u306b\u5b9f\u65bd\u3057\u307e\u3057\u305f\u3002\n\npip\u306e\u30a4\u30f3\u30b9\u30c8\u30fc\u30eb\nPython\u306e\u30d1\u30c3\u30b1\u30fc\u30b8\u7ba1\u7406pip\u3092\u30a4\u30f3\u30b9\u30c8\u30fc\u30eb\u3059\u308b\u3002\n\u516c\u5f0f\u30b5\u30a4\u30c8\u306e\u624b\u9806\u306b\u5f93\u3044\u3001\u4ee5\u4e0b\u3092\u5b9f\u884c\u3002\n$ sudo wget https://bootstrap.pypa.io/get-pip.py\n$ sudo python get-pip.py\n\nCollecting pip\n  Downloading pip-8.1.1-py2.py3-none-any.whl (1.2MB)\n    100% |\u2588\u2588\u2588\u2588\u2588\u2588\u2588\u2588\u2588\u2588\u2588\u2588\u2588\u2588\u2588\u2588\u2588\u2588\u2588\u2588\u2588\u2588\u2588\u2588\u2588\u2588\u2588\u2588\u2588\u2588\u2588\u2588| 1.2MB 49kB/s \nCollecting wheel\n  Downloading wheel-0.29.0-py2.py3-none-any.whl (66kB)\n    100% |\u2588\u2588\u2588\u2588\u2588\u2588\u2588\u2588\u2588\u2588\u2588\u2588\u2588\u2588\u2588\u2588\u2588\u2588\u2588\u2588\u2588\u2588\u2588\u2588\u2588\u2588\u2588\u2588\u2588\u2588\u2588\u2588| 71kB 290kB/s \nInstalling collected packages: pip, wheel\n  Found existing installation: pip 6.1.1\n    Uninstalling pip-6.1.1:\n      Successfully uninstalled pip-6.1.1\nSuccessfully installed pip-8.1.1 wheel-0.29.0\n\n\nmkdocs\u306e\u30a4\u30f3\u30b9\u30c8\u30fc\u30eb\n$ sudo pip install mkdocs\n\n\uff5e\uff5e\u7701\u7565\uff5e\uff5e\n\nException:\nTraceback (most recent call last):\n  File \"/usr/local/lib/python2.7/site-packages/pip/basecommand.py\", line 209, in main\n    status = self.run(options, args)\n  File \"/usr/local/lib/python2.7/site-packages/pip/commands/install.py\", line 317, in run\n    prefix=options.prefix_path,\n  File \"/usr/local/lib/python2.7/site-packages/pip/req/req_set.py\", line 732, in install\n    **kwargs\n  File \"/usr/local/lib/python2.7/site-packages/pip/req/req_install.py\", line 835, in install\n    self.move_wheel_files(self.source_dir, root=root, prefix=prefix)\n  File \"/usr/local/lib/python2.7/site-packages/pip/req/req_install.py\", line 1030, in move_wheel_files\n    isolated=self.isolated,\n  File \"/usr/local/lib/python2.7/site-packages/pip/wheel.py\", line 344, in move_wheel_files\n    clobber(source, lib_dir, True)\n  File \"/usr/local/lib/python2.7/site-packages/pip/wheel.py\", line 315, in clobber\n    ensure_dir(destdir)\n  File \"/usr/local/lib/python2.7/site-packages/pip/utils/__init__.py\", line 83, in ensure_dir\n    os.makedirs(path)\n  File \"/usr/lib64/python2.7/os.py\", line 157, in makedirs\n    mkdir(name, mode)\nOSError: [Errno 13] Permission denied: '/usr/local/lib/python2.7/site-packages/markdown'\n\npip\u304c\u6700\u65b0\u5316\u3057\u3066\u3044\u306a\u304b\u3063\u305f\u306e\u3092\u601d\u3044\u51fa\u3057\u3001\u4ee5\u4e0b\u3092\u5b9f\u884c\u3002\n$ pip install -U pip\nRequirement already up-to-date: pip in /usr/local/lib/python2.7/site-packages\n\n\u591a\u5206\u6210\u529f\u3002\n\u3061\u306a\u307f\u306b\u3001sudo\u3092\u3064\u3051\u305f\u3089\u30a8\u30e9\u30fc\u304c\u51fa\u305f\u30fb\u30fb\u30fb\u3053\u306e\u8fba\u3001\u758e\u3044\u306e\u3067\u8abf\u3079\u3066\u3082\u3044\u307e\u305b\u3093\u3002\u3002\u3002\n$ sudo pip install -U pip\nTraceback (most recent call last):\n  File \"/usr/bin/pip\", line 5, in <module>\n    from pkg_resources import load_entry_point\n  File \"/usr/lib/python2.7/dist-packages/pkg_resources/__init__.py\", line 3020, in <module>\n    working_set = WorkingSet._build_master()\n  File \"/usr/lib/python2.7/dist-packages/pkg_resources/__init__.py\", line 616, in _build_master\n    return cls._build_from_requirements(__requires__)\n  File \"/usr/lib/python2.7/dist-packages/pkg_resources/__init__.py\", line 629, in _build_from_requirements\n    dists = ws.resolve(reqs, Environment())\n  File \"/usr/lib/python2.7/dist-packages/pkg_resources/__init__.py\", line 807, in resolve\n    raise DistributionNotFound(req)\npkg_resources.DistributionNotFound: pip==6.1.1\n\n\u3093\uff1fsudo\u8981\u3089\u306a\u3044\uff1f\n\u3068\u3001\u601d\u3044\u7acb\u3061\u3001sudo\u7121\u3057\u3067\u5b9f\u884c\u3057\u3066\u307f\u308b\u3002\n$pip install mkdocs\nOSError: [Errno 13] Permission denied: '/usr/local/lib/python2.7/site-packages/markdown'\n\n\u3068\u306a\u308a\u3001\u3084\u3063\u3071\u308a\u540c\u3058\u30a8\u30e9\u30fc\u3002\u3002\u3002\n\u30a8\u30e9\u30fc\u7b87\u6240\u3092\u898b\u308b\u3068\u3001markdown\u304c\u7121\u3044\u3063\u307d\u3044\u306e\u3067\u3001pip\u3067\u30a4\u30f3\u30b9\u30c8\u30fc\u30eb\u3057\u3066\u307f\u308b\u3002\n$ pip install markdown\nOSError: [Errno 13] Permission denied: '/usr/local/lib/python2.7/site-packages/markdown'\n\n\u3068\u306a\u308a\u3001\u540c\u3058\u30a8\u30e9\u30fc\u3002\u3002\u3002\n\u3053\u3053\u3067\u6c17\u304c\u3064\u304f\u3002\n\u4f55\u304b\u30d1\u30b9\u304c\u9055\u304f\u306d\uff1f\n$ ls -l /usr/local/lib/python2.7/site-packages\ntotal 20\ndrwxr-xr-x 10 root root 4096 Apr  6 13:11 pip\ndrwxr-xr-x  2 root root 4096 Apr  6 13:11 pip-8.1.1.dist-info\n-rw-r--r--  1 root root  119 Dec  9 03:25 README\ndrwxr-xr-x  5 root root 4096 Apr  6 13:11 wheel\ndrwxr-xr-x  2 root root 4096 Apr  6 13:11 wheel-0.29.0.dist-info\n\n$ ls -l /usr/local/lib64/python2.7/site-packages/\ntotal 4\n-rw-r--r-- 1 root root 119 Dec  9 03:25 README\n\n\u3069\u3046\u3082sudo\u306b\u3088\u308bpath\u304c\u304a\u304b\u3057\u3044\u3088\u3046\u306b\u601d\u3046\u3002\n\u4e00\u5ea6pip\u3092\u5f37\u5236\u518d\u30a4\u30f3\u30b9\u30c8\u30fc\u30eb\u3059\u308b\u3002\n$ sudo python get-pip.py --force-reinstall\nCollecting pip\n  Using cached pip-8.1.1-py2.py3-none-any.whl\nInstalling collected packages: pip\n  Found existing installation: pip 8.1.1\n    Uninstalling pip-8.1.1:\n      Successfully uninstalled pip-8.1.1\nSuccessfully installed pip-8.1.1\n\n$ pip install mkdocs\n\n\uff5e\uff5e\u7701\u7565\uff5e\uff5e\n\nException:\nTraceback (most recent call last):\n  File \"/usr/local/lib/python2.7/site-packages/pip/basecommand.py\", line 209, in main\n    status = self.run(options, args)\n  File \"/usr/local/lib/python2.7/site-packages/pip/commands/install.py\", line 317, in run\n    prefix=options.prefix_path,\n  File \"/usr/local/lib/python2.7/site-packages/pip/req/req_set.py\", line 732, in install\n    **kwargs\n  File \"/usr/local/lib/python2.7/site-packages/pip/req/req_install.py\", line 835, in install\n    self.move_wheel_files(self.source_dir, root=root, prefix=prefix)\n  File \"/usr/local/lib/python2.7/site-packages/pip/req/req_install.py\", line 1030, in move_wheel_files\n    isolated=self.isolated,\n  File \"/usr/local/lib/python2.7/site-packages/pip/wheel.py\", line 344, in move_wheel_files\n    clobber(source, lib_dir, True)\n  File \"/usr/local/lib/python2.7/site-packages/pip/wheel.py\", line 315, in clobber\n    ensure_dir(destdir)\n  File \"/usr/local/lib/python2.7/site-packages/pip/utils/__init__.py\", line 83, in ensure_dir\n    os.makedirs(path)\n  File \"/usr/lib64/python2.7/os.py\", line 157, in makedirs\n    mkdir(name, mode)\nOSError: [Errno 13] Permission denied: '/usr/local/lib/python2.7/site-packages/markdown'\n\n\u3084\u3063\u3071\u308a\u30c0\u30e1\u30fb\u30fb\u30fb\u5fc3\u304c\u6298\u308c\u305f\u306e\u3067\u3001\u4e00\u6642\u4e2d\u65ad\u3002\n\n\u307e\u3068\u3081\n\n\u7d50\u5c40\u74b0\u5883\u69cb\u7bc9\u3067\u304d\u306a\u304b\u3063\u305f\nAmazon Linux\u306b\u3088\u308b\u6a29\u9650\u56de\u308a\u304c\u826f\u304f\u5206\u304b\u3063\u3066\u3044\u306a\u3044\nsudo\u306e\u6709\u7121\u3067\u53c2\u7167\u5148\u304c\u7570\u306a\u308b\u3088\u3046\u306a\u52d5\u304d\u6709\u308a\n\n\u6094\u3057\u3044\u306e\u3067\u3001\u518d\u30c1\u30e3\u30ec\u30f3\u30b8\u3057\u307e\u3059\uff01\uff01\n\u3061\u3087\u3063\u3068\u77e5\u3063\u305f[MkDocs](http://www.mkdocs.org/)\u3067\u3001\u904b\u7528\u624b\u9806\u66f8\u306a\u3093\u304b\u3092\u7ba1\u7406\u3067\u304d\u305f\u3089\u826f\u3044\u306a\u3001\u3068\u601d\u3044\u3001\u7c21\u5358\u306b\u74b0\u5883\u69cb\u7bc9\u3057\u3088\u3046\u3068\u3057\u305f\u306e\u304c\u59cb\u307e\u308a\u3002\n\n**\u6ce8\u610f\uff01\uff01**\n\u3053\u306e\u8a18\u4e8b\u306f\u7d50\u679c\u7684\u306b\u5931\u6557\u3057\u305f\u306e\u3067\u3001\u5b8c\u6210\u306f[\u3053\u3061\u3089\u306e\u8a18\u4e8b](http://qiita.com/w-matsumoto/items/1100fd5f21474e5bfe4d)\u53c2\u7167\u3057\u3066\u3044\u305f\u3060\u304d\u3001\u4ee5\u4e0b\u306e\u5931\u6557\u8ac7\u306f\u304b\u3063\u3068\u3070\u3057\u3066\u304f\u3060\u3055\u3044\u3002\u3002\u3002\n\uff08\u3053\u308c\u306f\u81ea\u5206\u306e\u5099\u5fd8\u9332\u7684\u306a\u3082\u306e\u3067\u3059\uff09\n\n# \u524d\u63d0\n\n* AWS\u306bAmazonLinux\u306eEC2\u3092\u6e96\u5099\u3057\u3066\u304a\u304f\n* `yum update`\u3092\u884c\u3044\u3001\u6700\u65b0\u72b6\u614b\u306b\u3057\u3066\u304a\u304f\n* \u5b9f\u884c\u30e6\u30fc\u30b6\u306f\u30c7\u30d5\u30a9\u30eb\u30c8\u306eec2-user\u3068\u3059\u308b\n* Python\u74b0\u5883\u306fAmazon Linux\u306e\u30c7\u30d5\u30a9\u30eb\u30c8\uff08Python 2.7.10\uff09\u3092\u7528\u3044\u308b\u3000\u203b2016/4/6\u6642\u70b9\n\n# \u74b0\u5883\u6e96\u5099\n\n[MkDocs\u3092\u4f7f\u3063\u3066\u30c9\u30ad\u30e5\u30e1\u30f3\u30c8\u306e\u30b5\u30a4\u30c8\u306e\u81ea\u52d5\u3067\u3053\u3057\u3089\u3048\u308b](http://qiita.com/keitarou/items/065d4311439cc6b6847d)\u3092\u53c2\u8003\u306b\u5b9f\u65bd\u3057\u307e\u3057\u305f\u3002\n\n## pip\u306e\u30a4\u30f3\u30b9\u30c8\u30fc\u30eb\n\nPython\u306e\u30d1\u30c3\u30b1\u30fc\u30b8\u7ba1\u7406[pip](https://pip.pypa.io/en/stable/)\u3092\u30a4\u30f3\u30b9\u30c8\u30fc\u30eb\u3059\u308b\u3002\n\u516c\u5f0f\u30b5\u30a4\u30c8\u306e\u624b\u9806\u306b\u5f93\u3044\u3001\u4ee5\u4e0b\u3092\u5b9f\u884c\u3002\n\n```\n$ sudo wget https://bootstrap.pypa.io/get-pip.py\n$ sudo python get-pip.py\n\nCollecting pip\n  Downloading pip-8.1.1-py2.py3-none-any.whl (1.2MB)\n    100% |\u2588\u2588\u2588\u2588\u2588\u2588\u2588\u2588\u2588\u2588\u2588\u2588\u2588\u2588\u2588\u2588\u2588\u2588\u2588\u2588\u2588\u2588\u2588\u2588\u2588\u2588\u2588\u2588\u2588\u2588\u2588\u2588| 1.2MB 49kB/s \nCollecting wheel\n  Downloading wheel-0.29.0-py2.py3-none-any.whl (66kB)\n    100% |\u2588\u2588\u2588\u2588\u2588\u2588\u2588\u2588\u2588\u2588\u2588\u2588\u2588\u2588\u2588\u2588\u2588\u2588\u2588\u2588\u2588\u2588\u2588\u2588\u2588\u2588\u2588\u2588\u2588\u2588\u2588\u2588| 71kB 290kB/s \nInstalling collected packages: pip, wheel\n  Found existing installation: pip 6.1.1\n    Uninstalling pip-6.1.1:\n      Successfully uninstalled pip-6.1.1\nSuccessfully installed pip-8.1.1 wheel-0.29.0\n```\n\n## mkdocs\u306e\u30a4\u30f3\u30b9\u30c8\u30fc\u30eb\n\n```\n$ sudo pip install mkdocs\n\n\uff5e\uff5e\u7701\u7565\uff5e\uff5e\n\nException:\nTraceback (most recent call last):\n  File \"/usr/local/lib/python2.7/site-packages/pip/basecommand.py\", line 209, in main\n    status = self.run(options, args)\n  File \"/usr/local/lib/python2.7/site-packages/pip/commands/install.py\", line 317, in run\n    prefix=options.prefix_path,\n  File \"/usr/local/lib/python2.7/site-packages/pip/req/req_set.py\", line 732, in install\n    **kwargs\n  File \"/usr/local/lib/python2.7/site-packages/pip/req/req_install.py\", line 835, in install\n    self.move_wheel_files(self.source_dir, root=root, prefix=prefix)\n  File \"/usr/local/lib/python2.7/site-packages/pip/req/req_install.py\", line 1030, in move_wheel_files\n    isolated=self.isolated,\n  File \"/usr/local/lib/python2.7/site-packages/pip/wheel.py\", line 344, in move_wheel_files\n    clobber(source, lib_dir, True)\n  File \"/usr/local/lib/python2.7/site-packages/pip/wheel.py\", line 315, in clobber\n    ensure_dir(destdir)\n  File \"/usr/local/lib/python2.7/site-packages/pip/utils/__init__.py\", line 83, in ensure_dir\n    os.makedirs(path)\n  File \"/usr/lib64/python2.7/os.py\", line 157, in makedirs\n    mkdir(name, mode)\nOSError: [Errno 13] Permission denied: '/usr/local/lib/python2.7/site-packages/markdown'\n```\n\npip\u304c\u6700\u65b0\u5316\u3057\u3066\u3044\u306a\u304b\u3063\u305f\u306e\u3092\u601d\u3044\u51fa\u3057\u3001\u4ee5\u4e0b\u3092\u5b9f\u884c\u3002\n\n```\n$ pip install -U pip\nRequirement already up-to-date: pip in /usr/local/lib/python2.7/site-packages\n```\n\n\u591a\u5206\u6210\u529f\u3002\n\u3061\u306a\u307f\u306b\u3001sudo\u3092\u3064\u3051\u305f\u3089\u30a8\u30e9\u30fc\u304c\u51fa\u305f\u30fb\u30fb\u30fb\u3053\u306e\u8fba\u3001\u758e\u3044\u306e\u3067\u8abf\u3079\u3066\u3082\u3044\u307e\u305b\u3093\u3002\u3002\u3002\n\n```\n$ sudo pip install -U pip\nTraceback (most recent call last):\n  File \"/usr/bin/pip\", line 5, in <module>\n    from pkg_resources import load_entry_point\n  File \"/usr/lib/python2.7/dist-packages/pkg_resources/__init__.py\", line 3020, in <module>\n    working_set = WorkingSet._build_master()\n  File \"/usr/lib/python2.7/dist-packages/pkg_resources/__init__.py\", line 616, in _build_master\n    return cls._build_from_requirements(__requires__)\n  File \"/usr/lib/python2.7/dist-packages/pkg_resources/__init__.py\", line 629, in _build_from_requirements\n    dists = ws.resolve(reqs, Environment())\n  File \"/usr/lib/python2.7/dist-packages/pkg_resources/__init__.py\", line 807, in resolve\n    raise DistributionNotFound(req)\npkg_resources.DistributionNotFound: pip==6.1.1\n```\n\n\u3093\uff1fsudo\u8981\u3089\u306a\u3044\uff1f\n\u3068\u3001\u601d\u3044\u7acb\u3061\u3001sudo\u7121\u3057\u3067\u5b9f\u884c\u3057\u3066\u307f\u308b\u3002\n\n```\n$pip install mkdocs\nOSError: [Errno 13] Permission denied: '/usr/local/lib/python2.7/site-packages/markdown'\n```\n\n\u3068\u306a\u308a\u3001\u3084\u3063\u3071\u308a\u540c\u3058\u30a8\u30e9\u30fc\u3002\u3002\u3002\n\u30a8\u30e9\u30fc\u7b87\u6240\u3092\u898b\u308b\u3068\u3001markdown\u304c\u7121\u3044\u3063\u307d\u3044\u306e\u3067\u3001pip\u3067\u30a4\u30f3\u30b9\u30c8\u30fc\u30eb\u3057\u3066\u307f\u308b\u3002\n\n```\n$ pip install markdown\nOSError: [Errno 13] Permission denied: '/usr/local/lib/python2.7/site-packages/markdown'\n```\n\n\u3068\u306a\u308a\u3001\u540c\u3058\u30a8\u30e9\u30fc\u3002\u3002\u3002\n\u3053\u3053\u3067\u6c17\u304c\u3064\u304f\u3002\n\u4f55\u304b\u30d1\u30b9\u304c\u9055\u304f\u306d\uff1f\n\n```\n$ ls -l /usr/local/lib/python2.7/site-packages\ntotal 20\ndrwxr-xr-x 10 root root 4096 Apr  6 13:11 pip\ndrwxr-xr-x  2 root root 4096 Apr  6 13:11 pip-8.1.1.dist-info\n-rw-r--r--  1 root root  119 Dec  9 03:25 README\ndrwxr-xr-x  5 root root 4096 Apr  6 13:11 wheel\ndrwxr-xr-x  2 root root 4096 Apr  6 13:11 wheel-0.29.0.dist-info\n```\n\n```\n$ ls -l /usr/local/lib64/python2.7/site-packages/\ntotal 4\n-rw-r--r-- 1 root root 119 Dec  9 03:25 README\n```\n\n\u3069\u3046\u3082sudo\u306b\u3088\u308bpath\u304c\u304a\u304b\u3057\u3044\u3088\u3046\u306b\u601d\u3046\u3002\n\u4e00\u5ea6pip\u3092\u5f37\u5236\u518d\u30a4\u30f3\u30b9\u30c8\u30fc\u30eb\u3059\u308b\u3002\n\n```\n$ sudo python get-pip.py --force-reinstall\nCollecting pip\n  Using cached pip-8.1.1-py2.py3-none-any.whl\nInstalling collected packages: pip\n  Found existing installation: pip 8.1.1\n    Uninstalling pip-8.1.1:\n      Successfully uninstalled pip-8.1.1\nSuccessfully installed pip-8.1.1\n```\n\n```\n$ pip install mkdocs\n\n\uff5e\uff5e\u7701\u7565\uff5e\uff5e\n\nException:\nTraceback (most recent call last):\n  File \"/usr/local/lib/python2.7/site-packages/pip/basecommand.py\", line 209, in main\n    status = self.run(options, args)\n  File \"/usr/local/lib/python2.7/site-packages/pip/commands/install.py\", line 317, in run\n    prefix=options.prefix_path,\n  File \"/usr/local/lib/python2.7/site-packages/pip/req/req_set.py\", line 732, in install\n    **kwargs\n  File \"/usr/local/lib/python2.7/site-packages/pip/req/req_install.py\", line 835, in install\n    self.move_wheel_files(self.source_dir, root=root, prefix=prefix)\n  File \"/usr/local/lib/python2.7/site-packages/pip/req/req_install.py\", line 1030, in move_wheel_files\n    isolated=self.isolated,\n  File \"/usr/local/lib/python2.7/site-packages/pip/wheel.py\", line 344, in move_wheel_files\n    clobber(source, lib_dir, True)\n  File \"/usr/local/lib/python2.7/site-packages/pip/wheel.py\", line 315, in clobber\n    ensure_dir(destdir)\n  File \"/usr/local/lib/python2.7/site-packages/pip/utils/__init__.py\", line 83, in ensure_dir\n    os.makedirs(path)\n  File \"/usr/lib64/python2.7/os.py\", line 157, in makedirs\n    mkdir(name, mode)\nOSError: [Errno 13] Permission denied: '/usr/local/lib/python2.7/site-packages/markdown'\n```\n\n\u3084\u3063\u3071\u308a\u30c0\u30e1\u30fb\u30fb\u30fb\u5fc3\u304c\u6298\u308c\u305f\u306e\u3067\u3001\u4e00\u6642\u4e2d\u65ad\u3002\n\n# \u307e\u3068\u3081\n\n* \u7d50\u5c40\u74b0\u5883\u69cb\u7bc9\u3067\u304d\u306a\u304b\u3063\u305f\n* Amazon Linux\u306b\u3088\u308b\u6a29\u9650\u56de\u308a\u304c\u826f\u304f\u5206\u304b\u3063\u3066\u3044\u306a\u3044\n* sudo\u306e\u6709\u7121\u3067\u53c2\u7167\u5148\u304c\u7570\u306a\u308b\u3088\u3046\u306a\u52d5\u304d\u6709\u308a\n\n\n\u6094\u3057\u3044\u306e\u3067\u3001\u518d\u30c1\u30e3\u30ec\u30f3\u30b8\u3057\u307e\u3059\uff01\uff01\n\n", "tags": ["Python", "MkDocs", "pip"]}